<?xml version="1.0"?>
<robot xmlns:xacro="http://ros.org/wiki/xacro">

<!-- Import Rviz colors -->
<xacro:include filename="$(find auto_driver_description)/urdf/auto_driver.material.xacro" />

<xacro:macro name="auto_driver" params="parent *origin">
  <joint name="origin_to_base_frame" type="fixed">
    <xacro:insert_block name="origin" />
    <parent link="${parent}" />
    <child link="base_frame" />
    <axis xyz="0 0 1" />
  </joint>

  <link name="base_frame">
    <visual>
      <origin xyz="0 0 0" rpy="0 -1.5708 0"/>
      <geometry>
        <mesh filename="package://auto_driver_description/meshes/base_frame.stl" scale="0.001 0.001 0.001"/>
      </geometry>
      <material name="grey"/>
    </visual>

    <collision>
      <origin xyz="0 0 0" rpy="0 0 0"/>
      <geometry>
        <mesh filename="package://auto_driver_description/meshes/base_frame.stl" scale="0.001 0.001 0.001"/>
      </geometry>
    </collision>

    <inertial>
      <origin xyz="3.0876154e-04 0.0000000e+00 -1.2176461e-04" />
      <mass value="7.9119962e-02" />
      <inertia ixx="1.2505234e-05" ixy="0.0" ixz="-1.7855208e-07"
               iyy="2.1898364e-05" iyz="0.0"
               izz="1.9267361e-05" />
    </inertial>
  </link>

  <link name="fake_1_to_2" />
  <joint name="fake_1_to_2_joint" type="fixed">
    <parent link="base_frame" />
    <child link="fake_1_to_2" />
    <origin xyz="0 0 0.18" rpy="0 0 0" />
  </joint>


  <joint name="yaw_joint" type="revolute">
    <parent link="fake_1_to_2"/>
    <child link="yaw_link"/>
    <origin xyz="0 0 0.005" rpy="0 0 0"/>
    <axis xyz="0 0 -1"/>
    <limit velocity="4.8" effort="1" lower="0.0" upper="2.0" />
  </joint>

  <link name="yaw_link">
    <visual>
      <origin xyz="0 -0.05 0.019" rpy="0 0 0"/>
      <geometry>
        <mesh filename="package://auto_driver_description/meshes/gimbal_yaw_link.stl" scale="0.001 0.001 0.001"/>
      </geometry>
      <material name="grey"/>
    </visual>

    <collision>
      <origin xyz="0 -0.05 0.019" rpy="0 0 0"/>
      <geometry>
        <mesh filename="package://auto_driver_description/meshes/gimbal_yaw_link.stl" scale="0.001 0.001 0.001"/>
      </geometry>
    </collision>

     <inertial>
      <origin xyz="-3.0184870e-04 5.4043684e-04 0.047433464e-02" />
      <mass value="9.8406837e-02" />
      <inertia ixx="3.4543422e-05" ixy="-1.6031095e-08" ixz="-3.8375155e-07"
               iyy="3.2689329e-05" iyz="2.8511935e-08"
               izz="1.8850320e-05" />
    </inertial>
  </link>
<!--  -->
  <link name="fake_2_to_3" />
  <joint name="fake_2_to_3_joint" type="fixed">
    <parent link="yaw_link" />
    <child link="fake_2_to_3" />
    <origin xyz="0 0 0" rpy="-1.57079632679 0 0" />
  </joint>

  <link name="pitch_link">
    <visual>
      <origin xyz="0 0 0.019" rpy="0 0 0"/>
      <geometry>
        <mesh filename="package://auto_driver_description/meshes/gimbal_pitch_link.stl" scale="0.001 0.001 0.001"/>
      </geometry>
      <material name="grey"/>
    </visual>

    <collision>
      <origin xyz="0 0 0.019" rpy="0 0 0"/>
      <geometry>
        <mesh filename="package://auto_driver_description/meshes/gimbal_pitch_link.stl" scale="0.001 0.001 0.001"/>
      </geometry>
    </collision>

     <inertial>
      <origin xyz="-3.0184870e-04 5.4043684e-04 0.047433464e-02" />
      <mass value="9.8406837e-02" />
      <inertia ixx="3.4543422e-05" ixy="-1.6031095e-08" ixz="-3.8375155e-07"
               iyy="3.2689329e-05" iyz="2.8511935e-08"
               izz="1.8850320e-05" />
    </inertial>
  </link>

  <joint name="pitch_joint" type="revolute">
    <parent link="fake_2_to_3"/>
    <child link="pitch_link"/>
    <origin xyz="0.0 0.0 0.005" rpy="0 0 0"/>
    <axis xyz="1 0 0"/>
    <limit velocity="4.8" effort="1" lower="0.0" upper="2.0" />
  </joint>

</xacro:macro>

</robot>